<?xml version="1.0" ?>
<robot xmlns:xacro="http://ros.org/wiki/xacro">

     <xacro:include filename="$(find terrasentia_description)/urdf/includes/materials.urdf.xacro"/>
     <xacro:include filename="$(find terrasentia_description)/urdf/includes/macros_test.urdf.xacro"/>
     <xacro:include filename="$(find terrasentia_sensors)/urdf/all_sensors.urdf.xacro" />
     <!-- ====================================================
                           Chassis
     ========================================================= -->
	<xacro:macro name="base_footprint" params="parent child">
		<link name="${parent}">
               <inertial>
                    <origin xyz="0 0 0" rpy="0 0 0" />
                    <mass value="0.000001" />
                    <inertia
                         ixx="0.00001"
                         ixy="0"
                         ixz="0"
                         iyy="0.00001"
                         iyz="0"
                         izz="0.00001" />
               </inertial>
			<visual>
				<origin rpy="0 0 0" xyz="0 0 0"/>
				<geometry>
					<box size="0.001 0.001 0.001"/>
				</geometry>
			</visual>
		</link>

		<joint name="base_footprint_joint" type="fixed">
			<origin rpy="0 0 1.5708" xyz="0 0 0"/>
			<parent link="${parent}"/>
			<child link="${child}"/>
		</joint>
	</xacro:macro>


     <xacro:macro name="chassis_v2" params="name stl_chassis stl_lid color simplified=false">
          <link name="${name}">
               <inertial>
                    <origin xyz="0 -0.01723 0.04522" rpy="0 0 0" />
                    <mass value="7.227" />
                    <inertia
                         ixx="0.09243"
                         ixy="0.00023"
                         ixz="0"
                         iyy="0.05913"
                         iyz="0.00445"
                         izz="0.146" />
               </inertial>
               <visual>
                    <origin xyz="-0.2325 0.264 -0.07325" rpy="1.5708 0 0" />
                    <geometry>
                         <mesh filename="${stl_chassis}" scale="0.001 0.001 0.001"/>
                    </geometry>
                    <xacro:color_material color="${color}"/>
               </visual>
               <collision>
				<xacro:if value="${simplified == 'true'}">
					<origin xyz="0 0 0.04545" rpy="0 0 0" />
					<geometry>
						<box size="0.35322 0.508 0.13136"/>
	                    </geometry>
				</xacro:if>
				<xacro:unless value="${simplified == 'true'}">
					<origin xyz="-0.2325 0.264 -0.07325" rpy="1.5708 0 0" />
	                    <geometry>
	                         <mesh filename="${stl_chassis}" scale="0.001 0.001 0.001" />
	                    </geometry>
				</xacro:unless>
               </collision>
          </link>

          <link name="lid_link">
               <inertial>
                    <origin xyz="-0.00997 0.12337 0.07276" rpy="0 0 0" />
                    <mass value="0.01" />
                    <inertia
                         ixx="0.0242"
                         ixy="0"
                         ixz="0.00011"
                         iyy="0.03556"
                         iyz="0"
                         izz="0.01136" />
               </inertial>
               <visual>
                    <origin xyz="0 0 0" rpy="0 0 0" />
                    <geometry>
                         <mesh filename="${stl_lid}" />
                    </geometry>
                    <xacro:color_material color="${color}"/>
               </visual>
               <collision>
                    <origin xyz="0 0 0" rpy="0 0 0" />
                    <geometry>
                         <mesh filename="${stl_lid}" />
                    </geometry>
               </collision>
          </link>

          <joint name="lid_joint" type="fixed">
               <origin xyz="0.00974 0.08522 0.00018" rpy="1.5708 0 0" />
               <parent link="${name}" />
               <child link="lid_link" />
               <axis xyz="0 0 0" />
          </joint>

          <xacro:add_friction_gazebo parent="${name}" mu1="1.0" mu2="1.0" fdir1="0 0 0" />
          <xacro:color_gazebo parent="${name}" color="${color}"/>
          <xacro:color_gazebo parent="lid_link" color="${color}"/>
     </xacro:macro>


	<!-- ====================================================
                           Leg Links
     ========================================================= -->
     <xacro:macro name="leg_type_1" params="parent prefix suffix stl min max damping stiffness spring_reference reflect color *origin_inertial simplified=false verbose=false" >
          <link name="${prefix}_${suffix}_leg_link">
               <inertial>
				<mass value="0.735" />

                    <xacro:insert_block name="origin_inertial"/>
				<xacro:if value="${prefix == 'front'}">
					<inertia ixx="0.0036088" ixy="0.0000305" ixz="0.0008925" iyy="0.0029930" iyz="-0.0000678" izz="0.0022653" />
				</xacro:if>
				<xacro:unless value="${prefix == 'front'}">
					<inertia ixx="0.0037482" ixy="0.0000302" ixz="0.000768" iyy="0.0029930" iyz="-0.0000679" izz="0.0021259" />
				</xacro:unless>

               </inertial>
               <visual>
                    <origin xyz="0 0 0" rpy="0 0 0" />
                    <geometry>
                         <mesh filename="${stl}" />
                    </geometry>
                    <xacro:color_material color="${color}"/>
               </visual>
               <collision>
				<xacro:if value="${simplified == 'true'}">
					<origin xyz="0 -0.056 -0.083" rpy="0 0 0" />
	                    <geometry>
	                         <box size="0.045 0.118 0.215" />
	                    </geometry>
				</xacro:if>
				<xacro:unless value="${simplified == 'true'}">
					<origin xyz="0 0 0" rpy="0 0 0" />
	                    <geometry>
	                         <mesh filename="${stl}" />
	                    </geometry>
				</xacro:unless>
               </collision>
          </link>

		<joint name="${prefix}_${suffix}_leg_joint" type="revolute">
               <parent link="${parent}" />
               <child link="${prefix}_${suffix}_leg_link" />
			<limit effort="10000" velocity="10000" lower="${min}" upper="${max}" />
			<dynamics damping="${damping}" spring_stiffness="${stiffness}" spring_reference="${spring_reference}" />

			<xacro:if value="${suffix == 'right'}">
				<axis xyz="0 -1 0" />
				<xacro:if value="${prefix == 'rear'}">
					<origin xyz="${9.5 * -0.01366} ${reflect * 0.04356} 0.03553" rpy="0 -1.12663 ${reflect * 1.5708}" />
				</xacro:if>
				<xacro:unless value="${prefix == 'rear'}">
					<origin xyz="-0.01366 ${reflect * 0.04356} 0.03553" rpy="0 -1.12663 ${reflect * 1.5708}" />
				</xacro:unless>
			</xacro:if>
			<xacro:unless value="${suffix == 'right'}">
				<axis xyz="0 1 0" />
				<xacro:if value="${prefix == 'rear'}">
					<origin xyz="${9.5 * 0.13031} ${reflect * 0.04356} 0.03553" rpy="0 -1.12663 ${reflect * 1.5708}" />
				</xacro:if>
				<xacro:unless value="${prefix == 'rear'}">
					<origin xyz="0.13031 ${reflect * 0.04356} 0.03553" rpy="0 -1.12663 ${reflect * 1.5708}" />
				</xacro:unless>

			</xacro:unless>
          </joint>

          <gazebo>
               <plugin name="spring_plugin_${prefix}_${suffix}" filename="libTorsionalSpringPlugin.so" >
                    <joint_handle>${prefix}_${suffix}_leg_joint</joint_handle>
                    <spring_stiffness>${stiffness}</spring_stiffness>
                    <spring_damping>${damping}</spring_damping>
                    <spring_reference>${spring_reference}</spring_reference>
                    <verbose>${verbose}</verbose>
               </plugin>
          </gazebo>
          <xacro:color_gazebo parent="${prefix}_${suffix}_leg_link" color="${color}"/>

     </xacro:macro>


     <xacro:macro name="leg_type_2" params="parent prefix suffix stl min max damping reflect stiffness spring_reference color *origin_inertial simplified=false verbose=false" >
          <link name="${prefix}_${suffix}_leg_link">
               <inertial>
				<mass value="0.735" />

                    <xacro:insert_block name="origin_inertial"/>
				<xacro:if value="${prefix == 'front'}">
					<inertia ixx="0.0036088" ixy="0.0000305" ixz="0.0008925" iyy="0.0029930" iyz="-0.0000678" izz="0.0022653" />
				</xacro:if>
				<xacro:unless value="${prefix == 'front'}">
					<inertia ixx="0.0037482" ixy="0.0000302" ixz="0.000768" iyy="0.0029930" iyz="-0.0000679" izz="0.0021259" />
				</xacro:unless>

               </inertial>
               <visual>
                    <origin xyz="0 0 0" rpy="0 0 0" />
                    <geometry>
                         <mesh filename="${stl}" />
                    </geometry>
                    <xacro:color_material color="${color}"/>
               </visual>
               <collision>
				<xacro:if value="${simplified == 'true'}">
					<origin xyz="0 0.056 0.083" rpy="0 0 0" />
	                    <geometry>
	                         <box size="0.045 0.118 0.215" />
	                    </geometry>
				</xacro:if>
				<xacro:unless value="${simplified == 'true'}">
					<origin xyz="0 0 0" rpy="0 0 0" />
	                    <geometry>
	                         <mesh filename="${stl}" />
	                    </geometry>
				</xacro:unless>
               </collision>
          </link>

		<joint name="${prefix}_${suffix}_leg_joint" type="revolute">
               <parent link="${parent}" />
               <child link="${prefix}_${suffix}_leg_link" />
			<limit effort="10000" velocity="10000" lower="${min}" upper="${max}" />
			<dynamics damping="${damping}" spring_stiffness="${stiffness}" spring_reference="${spring_reference}" />

			<xacro:if value="${suffix == 'right'}">
				<axis xyz="0 -1 0" />
                    <xacro:if value="${prefix == 'rear'}">
					<origin xyz="${0.1 * -0.01366} ${reflect * 0.04356} 0.03553" rpy="3.14159 -1.12663 ${reflect * 1.5708}" />
				</xacro:if>
				<xacro:unless value="${prefix == 'rear'}">
					<origin xyz="-0.01366 ${reflect * 0.04356} 0.03553" rpy="3.14159 -1.12663 ${reflect * 1.5708}" />
				</xacro:unless>
			</xacro:if>
			<xacro:unless value="${suffix == 'right'}">
				<axis xyz="0 1 0" />
                    <xacro:if value="${prefix == 'rear'}">
					<origin xyz="${0.1 * 0.13031} ${reflect * 0.04356} 0.03553" rpy="3.14159 -1.12663 ${reflect * 1.5708}" />
				</xacro:if>
				<xacro:unless value="${prefix == 'rear'}">
					<origin xyz="0.13031 ${reflect * 0.04356} 0.03553" rpy="3.14159 -1.12663 ${reflect * 1.5708}" />
				</xacro:unless>
			</xacro:unless>
          </joint>

          <gazebo>
               <plugin name="spring_plugin_${prefix}_${suffix}" filename="libTorsionalSpringPlugin.so" >
                    <joint_handle>${prefix}_${suffix}_leg_joint</joint_handle>
                    <spring_stiffness>${stiffness}</spring_stiffness>
                    <spring_damping>${damping}</spring_damping>
                    <spring_reference>${spring_reference}</spring_reference>
				<verbose>${verbose}</verbose>
               </plugin>
          </gazebo>

          <xacro:color_gazebo parent="${prefix}_${suffix}_leg" color="${color}"/>

     </xacro:macro>

	<!-- ====================================================
                           Wheel Links
     ========================================================= -->
     <xacro:macro name="wheel" params="parent prefix suffix stl reflect color friction simplified=false scale=1">
          <link name="${prefix}_${suffix}_wheel_link">
			<inertial>
                    <origin xyz="0 -0.02126 0" rpy="0 0 0" />
                    <mass value="0.34" />
                    <inertia
                         ixx="0.001"
                         ixy="0.0"
                         ixz="0.0"
                         iyy="0.001"
                         iyz="0.0"
                         izz="0.00001" />
               </inertial>
               <visual>
                    <origin xyz="0 0 0" rpy="0 0 0" />
                    <geometry>
                         <mesh filename="${stl}" scale="${scale} ${scale} ${scale}"/>
                    </geometry>
                    <xacro:color_material color="${color}"/>
               </visual>
               <collision>
				<xacro:if value="${simplified == 'true'}">
					<origin xyz="0 -0.021 0" rpy="1.5708 0 0" />
	                    <geometry>
	                         <cylinder length="0.042" radius="0.1"/>
	                    </geometry>
				</xacro:if>
				<xacro:unless value="${simplified == 'true'}">
					<origin xyz="0 0 0" rpy="0 0 0" />
	                    <geometry>
	                         <mesh filename="${stl}" scale="${scale} ${scale} ${scale}"/>
	                    </geometry>
				</xacro:unless>
               </collision>
          </link>

		<joint name="${prefix}_${suffix}_wheel_joint" type="continuous">
               <parent link="${prefix}_${suffix}_leg_link" />
               <child link="${prefix}_${suffix}_wheel_link" />

			<xacro:if value="${suffix == 'right'}">
                    <axis xyz="0 1 0" />
                    <xacro:if value="${prefix == 'rear'}">
					<origin xyz="0 ${0.1 * 0.12293} ${reflect*0.17041}" rpy="0 0 3.14159" />
				</xacro:if>
				<xacro:unless value="${prefix == 'rear'}">
					<origin xyz="0 0.12293 ${reflect*0.17041}" rpy="0 0 3.14159" />
				</xacro:unless>
			</xacro:if>
			<xacro:unless value="${suffix == 'right'}">
                    <axis xyz="0 -1 0" />
                    <xacro:if value="${prefix == 'rear'}">
					<origin xyz="0 ${15.25 * 0.00793} ${-reflect*0.17041}" rpy="0 0 3.14159" />
				</xacro:if>
				<xacro:unless value="${prefix == 'rear'}">
					<origin xyz="0 0.00793 ${-reflect*0.17041}" rpy="0 0 3.14159" />
				</xacro:unless>
			</xacro:unless>

			<dynamics damping="0.7"/>
          </joint>

          <xacro:add_friction_gazebo parent="${prefix}_${suffix}_wheel_link" mu1="${friction}" mu2="${friction}" fdir1="0 0 0" />
          <xacro:color_gazebo parent="${prefix}_${suffix}_wheel_link" color="${color}"/>

     </xacro:macro>

     <!-- ====================================================
                    Front Camera Gimbal Assembly
     ========================================================= -->
     <xacro:macro name="front_camera_gimbal_assembly" params="parent" >
          <link name="front_camera_gimbal_link">
               <inertial>
                    <origin xyz="0.01014 -0.01943 0.0035" rpy="0 0 0" />
                    <mass value="0.006" />
                    <inertia
                         ixx="0.000001"
                         ixy="0.0"
                         ixz="0.0"
                         iyy="0.000001"
                         iyz="0.0"
                         izz="0.000001" />
               </inertial>
               <visual>
                    <origin xyz="0 0 0" rpy="0 ${-1.26059+1.5708} 0" />
                    <geometry>
                         <mesh filename="package://terrasentia_description/meshes/v2/front_camera_gimbal_link.STL" />
                    </geometry>
                    <material name="">
                         <color rgba="0.792156862745098 0.819607843137255 0.933333333333333 1" />
                    </material>
               </visual>
               <collision>
                    <origin xyz="0 ${-0.02389} 0" rpy="0 0 0" />
                    <geometry>
                         <box size="${0.02828*2} ${0.02389*2} ${0.02828*2}"/>
                    </geometry>
               </collision>
          </link>

          <!-- <joint name="front_camera_gimbal_joint" type="continuous">
               <origin xyz="0.0264 -0.24222 0.10914" rpy="0 0 -1.5708" />
               <parent link="base_link" />
               <child link="front_camera_gimbal_link" />
               <axis xyz="0 1 0" />
          </joint> -->

          <joint name="front_camera_gimbal_joint" type="revolute">
               <origin xyz="0.0264 -0.24222 0.10914" rpy="0 0 -1.5708" />
               <parent link="${parent}" />
               <child link="front_camera_gimbal_link" />
               <axis xyz="0 1 0" />
			<limit
                    lower="-1.74533"
                    upper="1.74533"
                    effort="10000"
                    velocity="10000" />
               <dynamics damping="0"/>
          </joint>

          <xacro:sensor_imu_terra name="front_gimbal_imu" parent="front_camera_gimbal_link" color="red"
                         update_rate="100.0"
                         noise="0.005"
                         yaw_offset="0.0"
                         yaw_drift="0.02"
                         yaw_noise="0.01"
                         rate_offset="0.0 0.0 0.0"
                         rate_drift="0.002 0.002 0.002"
                         rate_noise="0.001 0.001 0.001"
                         accel_offset="0.0 0.0 0.0"
                         accel_drift="0.005 0.005 0.005"
                         accel_noise="0.005 0.005 0.005">
               <origin xyz="0 -0.028 0.002" rpy="0 1.5708 0"/>
          </xacro:sensor_imu_terra>

          <xacro:sensor_elp_usb_cam name="camera" parent="front_camera_gimbal_link" color="purple">
               <origin xyz="0.025 -0.028 0.002" rpy="0 0 0"/>
          </xacro:sensor_elp_usb_cam>


          <gazebo>
               <plugin name="front_gimbal_controller" filename="libCameraGimbalPlugin.so">
				<!-- ROS-specific Parameters -->
				<robotNamespace></robotNamespace>
                    <jointHandle>front_camera_gimbal_joint</jointHandle>
                    <gimbalSpeedTopic>cmd_vel</gimbalSpeedTopic>
                    <targetAngleParamName>/front_gimbal_target</targetAngleParamName>
                    <imuTopic>front_gimbal_imu</imuTopic>
                    <useImuAxis>4</useImuAxis>
				<!-- PID-Specific Parameters -->
				<updateRate>100.0</updateRate>
                    <imuDegreeOffset>-180.0</imuDegreeOffset>
				<defaultTargetAngle>45.0</defaultTargetAngle>
                    <kP>1.25</kP>
                    <kI>0.0</kI>
                    <kD>0.0</kD>
				<!-- Max/Min Limits -->
				<maxJointAngle>180.0</maxJointAngle>
				<minJointAngle>-180.0</minJointAngle>
				<maxCommandSignal>20</maxCommandSignal>
				<minCommandSignal>-20</minCommandSignal>
				<maxIntegralErr>1.0</maxIntegralErr>
				<minIntegralErr>-1.0</minIntegralErr>
				<!-- Miscellaneous Parameters -->
				<controlGain>2.0</controlGain>
				<torque>5</torque>
				<!-- Flags -->
                    <verbose>true</verbose>
                    <useOffset>true</useOffset>
				<flipControlDirection>false</flipControlDirection>
				<flipJointAngleDirection>true</flipJointAngleDirection>
               </plugin>
          </gazebo>


     </xacro:macro>

     <!-- ====================================================
                    Left Camera Gimbal Assembly
     ========================================================= -->
     <xacro:macro name="left_camera_gimbal_assembly" params="parent" >
          <link name="left_camera_gimbal_link">
               <inertial>
                    <origin xyz="0.01014 -0.01943 0.0035" rpy="0 0 0" />
                    <mass value="0.006" />
                    <inertia
                         ixx="0.000001"
                         ixy="0.0"
                         ixz="0.0"
                         iyy="0.000001"
                         iyz="0.0"
                         izz="0.000001" />
               </inertial>
               <visual>
                    <origin xyz="0 0 0" rpy="0 ${-1.26059+1.5708} 0" />
                    <geometry>
                         <mesh filename="package://terrasentia_description/meshes/v2/left_camera_gimbal_link.STL" />
                    </geometry>
                    <material name="">
                         <color rgba="0.792156862745098 0.819607843137255 0.933333333333333 1" />
                    </material>
               </visual>
               <collision>
                    <origin xyz="0 ${-0.02389} 0" rpy="0 0 0" />
                    <geometry>
                         <box size="${0.02828*2} ${0.02389*2} ${0.02828*2}"/>
                    </geometry>
               </collision>
          </link>

          <joint name="left_camera_gimbal_joint" type="continuous">
               <origin xyz="0.16483 -0.07811 0.10914" rpy="0 0 0" />
               <parent link="${parent}" />
               <child link="left_camera_gimbal_link" />
               <axis xyz="0 -1 0" />
          </joint>

          <xacro:sensor_imu_terra name="left_gimbal_imu" parent="left_camera_gimbal_link" color="red"
                         update_rate="50.0"
                         noise="0.005"
                         yaw_offset="0.0"
                         yaw_drift="0.02"
                         yaw_noise="0.01"
                         rate_offset="0.0 0.0 0.0"
                         rate_drift="0.002 0.002 0.002"
                         rate_noise="0.001 0.001 0.001"
                         accel_offset="0.0 0.0 0.0"
                         accel_drift="0.005 0.005 0.005"
                         accel_noise="0.005 0.005 0.005">
               <origin xyz="0 -0.028 0.002" rpy="0 1.5708 0"/>
          </xacro:sensor_imu_terra>

          <xacro:sensor_elp_usb_cam name="left_camera" parent="left_camera_gimbal_link" color="purple">
               <origin xyz="0.025 -0.028 0.002" rpy="0 0 0"/>
          </xacro:sensor_elp_usb_cam>


     </xacro:macro>


     <!-- ====================================================
                    Right Camera Gimbal Assembly
     ========================================================= -->
     <xacro:macro name="right_camera_gimbal_assembly" params="parent" >
          <link name="right_camera_gimbal_link">
               <inertial>
                    <origin xyz="0 ${-0.02389} 0" rpy="0 0 0" />
                    <mass value="0.006" />
                    <inertia
                         ixx="0.000001"
                         ixy="0.0"
                         ixz="0.0"
                         iyy="0.000001"
                         iyz="0.0"
                         izz="0.000001" />
               </inertial>
               <visual>
                    <origin xyz="0 ${-2*0.02389} 0" rpy="0 ${-1.26059+1.5708} 0" />
                    <geometry>
                         <mesh filename="package://terrasentia_description/meshes/v2/right_camera_gimbal_link.STL" />
                    </geometry>
                    <material name="">
                         <color rgba="0.792156862745098 0.819607843137255 0.933333333333333 1" />
                    </material>
               </visual>
               <collision>
                    <origin xyz="0 ${-0.02389} 0" rpy="0 0 0" />
                    <geometry>
                         <box size="${0.02828*2} ${0.02389*2} ${0.02828*2}"/>
                    </geometry>
               </collision>
          </link>

          <joint name="right_camera_gimbal_joint" type="continuous">
               <origin xyz="-0.16483 -0.05479 0.10914" rpy="0 3.14159 0" />
               <parent link="${parent}" />
               <child link="right_camera_gimbal_link" />
               <axis xyz="0 1 0" />
          </joint>

          <xacro:sensor_imu_terra name="right_gimbal_imu" parent="right_camera_gimbal_link" color="red"
                         update_rate="50.0"
                         noise="0.005"
                         yaw_offset="0.0"
                         yaw_drift="0.02"
                         yaw_noise="0.01"
                         rate_offset="0.0 0.0 0.0"
                         rate_drift="0.002 0.002 0.002"
                         rate_noise="0.001 0.001 0.001"
                         accel_offset="0.0 0.0 0.0"
                         accel_drift="0.005 0.005 0.005"
                         accel_noise="0.005 0.005 0.005">
               <origin xyz="0 -0.028 0.002" rpy="0 1.5708 0"/>
          </xacro:sensor_imu_terra>

          <xacro:sensor_elp_usb_cam name="right_camera" parent="right_camera_gimbal_link" color="purple">
               <origin xyz="0.025 -0.026 0" rpy="0 0 0"/>
          </xacro:sensor_elp_usb_cam>

     </xacro:macro>





</robot>
